2024-03-21T07:53:31 {"cpu": 2.67919921875, "cpu_total": 8, "cpu_usage": 0.33489990234375, "memory": 1889.0, "memory_total": 8865.0, "memory_usage": 0.21308516638465877, "pipeline_run_id": 6169, "pipeline_schedule_id": 3, "pipeline_uuid": "etl_pipeline", "hostname": "3353dc602115", "level": "INFO", "message": "Pipeline etl_pipeline for run 6169 in schedule 3 is alive.", "timestamp": 1711007611.844761, "uuid": "a0d608009d6949889d21f06468a583bd"}
2024-03-21T07:53:31 {"cpu": 2.67919921875, "cpu_total": 8, "cpu_usage": 0.33489990234375, "memory": 1926.0, "memory_total": 8865.0, "memory_usage": 0.21725888324873097, "pipeline_run_id": 6169, "pipeline_schedule_id": 3, "pipeline_uuid": "etl_pipeline", "hostname": "3353dc602115", "level": "INFO", "message": "Pipeline etl_pipeline for run 6169 in schedule 3 is alive.", "timestamp": 1711007611.922936, "uuid": "a2ce6b72705d485684ad5738abd3f432"}
2024-03-21T07:53:31 {"block_run_id": 18502, "block_uuid": "api_load_data", "pipeline_run_id": 6169, "pipeline_schedule_id": 3, "pipeline_uuid": "etl_pipeline", "hostname": "3353dc602115", "level": "INFO", "message": "Execute PipelineRun 6169, BlockRun 18502: pipeline etl_pipeline block api_load_data", "timestamp": 1711007611.94075, "uuid": "51e5d7b67a6d481d94c96badad79d1f8"}
2024-03-21T07:53:32 {"block_run_id": 18502, "block_uuid": "api_load_data", "pipeline_run_id": 6169, "pipeline_schedule_id": 3, "pipeline_uuid": "etl_pipeline", "hostname": "3353dc602115", "level": "INFO", "message": "BlockRun 18502 (block_uuid: api_load_data) completes.", "timestamp": 1711007612.539542, "uuid": "44a140951c2a41d9abe80292ed25e896"}
2024-03-21T07:53:42 {"cpu": 2.666015625, "cpu_total": 8, "cpu_usage": 0.333251953125, "memory": 1897.0, "memory_total": 8865.0, "memory_usage": 0.21398759165256628, "pipeline_run_id": 6169, "pipeline_schedule_id": 3, "pipeline_uuid": "etl_pipeline", "hostname": "3353dc602115", "level": "INFO", "message": "Pipeline etl_pipeline for run 6169 in schedule 3 is alive.", "timestamp": 1711007622.037992, "uuid": "92c5d7ceb96040d88ed6f7271019fd08"}
2024-03-21T07:53:42 {"block_run_id": 18503, "block_uuid": "transform_data", "pipeline_run_id": 6169, "pipeline_schedule_id": 3, "pipeline_uuid": "etl_pipeline", "hostname": "3353dc602115", "level": "INFO", "message": "Execute PipelineRun 6169, BlockRun 18503: pipeline etl_pipeline block transform_data", "timestamp": 1711007622.134007, "uuid": "5f727c8cf8b7460fa7647f61443d6a7f"}
2024-03-21T07:53:42 {"block_run_id": 18503, "block_uuid": "transform_data", "pipeline_run_id": 6169, "pipeline_schedule_id": 3, "pipeline_uuid": "etl_pipeline", "hostname": "3353dc602115", "level": "INFO", "message": "BlockRun 18503 (block_uuid: transform_data) completes.", "timestamp": 1711007622.21488, "uuid": "b9ac71b4c8444d6089d8a45ae749fa61"}
2024-03-21T07:53:51 {"cpu": 2.6640625, "cpu_total": 8, "cpu_usage": 0.3330078125, "memory": 1901.0, "memory_total": 8865.0, "memory_usage": 0.21443880428652, "pipeline_run_id": 6169, "pipeline_schedule_id": 3, "pipeline_uuid": "etl_pipeline", "hostname": "3353dc602115", "level": "INFO", "message": "Pipeline etl_pipeline for run 6169 in schedule 3 is alive.", "timestamp": 1711007631.20791, "uuid": "2fee3c3482974cac9d2ba178e56edb8c"}
2024-03-21T07:53:51 {"block_run_id": 18504, "block_uuid": "export_to_postgres", "pipeline_run_id": 6169, "pipeline_schedule_id": 3, "pipeline_uuid": "etl_pipeline", "hostname": "3353dc602115", "level": "INFO", "message": "Execute PipelineRun 6169, BlockRun 18504: pipeline etl_pipeline block export_to_postgres", "timestamp": 1711007631.293862, "uuid": "4fcd2b91cc864142999ea0d06b075a59"}
2024-03-21T07:53:51 {"block_run_id": 18504, "block_uuid": "export_to_postgres", "pipeline_run_id": 6169, "pipeline_schedule_id": 3, "pipeline_uuid": "etl_pipeline", "hostname": "3353dc602115", "level": "EXCEPTION", "message": "BlockRun 18504 (block_uuid: export_to_postgres) failed.", "timestamp": 1711007631.374003, "uuid": "e1d88276ae6e40f4bed35bf69c9649fd", "error": ["Traceback (most recent call last):\n  File \"/usr/local/lib/python3.10/site-packages/mage_ai/data_preparation/executors/block_executor.py\", line 613, in execute\n    result = __execute_with_retry()\n  File \"/usr/local/lib/python3.10/site-packages/mage_ai/shared/retry.py\", line 54, in retry_func\n    raise e\n  File \"/usr/local/lib/python3.10/site-packages/mage_ai/shared/retry.py\", line 38, in retry_func\n    return func(*args, **kwargs)\n  File \"/usr/local/lib/python3.10/site-packages/mage_ai/data_preparation/executors/block_executor.py\", line 588, in __execute_with_retry\n    return self._execute(\n  File \"/usr/local/lib/python3.10/site-packages/mage_ai/data_preparation/executors/block_executor.py\", line 1077, in _execute\n    result = self.block.execute_sync(\n  File \"/usr/local/lib/python3.10/site-packages/mage_ai/data_preparation/models/block/__init__.py\", line 1314, in execute_sync\n    raise err\n  File \"/usr/local/lib/python3.10/site-packages/mage_ai/data_preparation/models/block/__init__.py\", line 1223, in execute_sync\n    output = self.execute_block(\n  File \"/usr/local/lib/python3.10/site-packages/mage_ai/data_preparation/models/block/__init__.py\", line 1529, in execute_block\n    outputs = self._execute_block(\n  File \"/usr/local/lib/python3.10/site-packages/mage_ai/data_preparation/models/block/__init__.py\", line 1685, in _execute_block\n    outputs = self.execute_block_function(\n  File \"/usr/local/lib/python3.10/site-packages/mage_ai/data_preparation/models/block/__init__.py\", line 1724, in execute_block_function\n    output = block_function_updated(*input_vars, **global_vars)\n  File \"<string>\", line 25, in export_data_to_postgres\n  File \"/usr/local/lib/python3.10/site-packages/mage_ai/io/sql.py\", line 279, in export\n    df = clean_df_for_export(df, self.clean, dtypes)\n  File \"/usr/local/lib/python3.10/site-packages/mage_ai/io/export_utils.py\", line 90, in clean_df_for_export\n    copy_df = df.copy()\nAttributeError: 'int' object has no attribute 'copy'\n"], "error_stack": [["  File \"/usr/local/bin/mage\", line 8, in <module>\n    sys.exit(app())\n", "  File \"/usr/local/lib/python3.10/site-packages/typer/main.py\", line 311, in __call__\n    return get_command(self)(*args, **kwargs)\n", "  File \"/usr/local/lib/python3.10/site-packages/click/core.py\", line 1130, in __call__\n    return self.main(*args, **kwargs)\n", "  File \"/usr/local/lib/python3.10/site-packages/typer/core.py\", line 778, in main\n    return _main(\n", "  File \"/usr/local/lib/python3.10/site-packages/typer/core.py\", line 216, in _main\n    rv = self.invoke(ctx)\n", "  File \"/usr/local/lib/python3.10/site-packages/click/core.py\", line 1657, in invoke\n    return _process_result(sub_ctx.command.invoke(sub_ctx))\n", "  File \"/usr/local/lib/python3.10/site-packages/click/core.py\", line 1404, in invoke\n    return ctx.invoke(self.callback, **ctx.params)\n", "  File \"/usr/local/lib/python3.10/site-packages/click/core.py\", line 760, in invoke\n    return __callback(*args, **kwargs)\n", "  File \"/usr/local/lib/python3.10/site-packages/typer/main.py\", line 683, in wrapper\n    return callback(**use_params)  # type: ignore\n", "  File \"/usr/local/lib/python3.10/site-packages/mage_ai/cli/main.py\", line 163, in start\n    start_server(\n", "  File \"/usr/local/lib/python3.10/site-packages/mage_ai/server/server.py\", line 743, in start_server\n    scheduler_manager.start_scheduler()\n", "  File \"/usr/local/lib/python3.10/site-packages/mage_ai/server/scheduler_manager.py\", line 87, in start_scheduler\n    proc.start()\n", "  File \"/usr/local/lib/python3.10/multiprocessing/process.py\", line 121, in start\n    self._popen = self._Popen(self)\n", "  File \"/usr/local/lib/python3.10/multiprocessing/context.py\", line 224, in _Popen\n    return _default_context.get_context().Process._Popen(process_obj)\n", "  File \"/usr/local/lib/python3.10/multiprocessing/context.py\", line 281, in _Popen\n    return Popen(process_obj)\n", "  File \"/usr/local/lib/python3.10/multiprocessing/popen_fork.py\", line 19, in __init__\n    self._launch(process_obj)\n", "  File \"/usr/local/lib/python3.10/multiprocessing/popen_fork.py\", line 71, in _launch\n    code = process_obj._bootstrap(parent_sentinel=child_r)\n", "  File \"/usr/local/lib/python3.10/multiprocessing/process.py\", line 314, in _bootstrap\n    self.run()\n", "  File \"/usr/local/lib/python3.10/multiprocessing/process.py\", line 108, in run\n    self._target(*self._args, **self._kwargs)\n", "  File \"/usr/local/lib/python3.10/site-packages/mage_ai/orchestration/db/process.py\", line 15, in start_session_and_run\n    results = target(*args)\n", "  File \"/usr/local/lib/python3.10/site-packages/mage_ai/server/scheduler_manager.py\", line 50, in run_scheduler\n    LoopTimeTrigger().start()\n", "  File \"/usr/local/lib/python3.10/site-packages/mage_ai/orchestration/triggers/loop_time_trigger.py\", line 14, in start\n    self.run()\n", "  File \"/usr/local/lib/python3.10/site-packages/mage_ai/orchestration/triggers/time_trigger.py\", line 11, in run\n    schedule_all()\n", "  File \"/usr/local/lib/python3.10/site-packages/mage_ai/orchestration/pipeline_scheduler_original.py\", line 1643, in schedule_all\n    PipelineScheduler(r).schedule()\n", "  File \"/usr/local/lib/python3.10/site-packages/mage_ai/orchestration/db/__init__.py\", line 157, in func_with_rollback\n    return func(*args, **kwargs)\n", "  File \"/usr/local/lib/python3.10/site-packages/mage_ai/orchestration/pipeline_scheduler_original.py\", line 318, in schedule\n    self.__schedule_blocks(block_runs)\n", "  File \"/usr/local/lib/python3.10/site-packages/mage_ai/orchestration/pipeline_scheduler_original.py\", line 602, in __schedule_blocks\n    job_manager.add_job(\n", "  File \"/usr/local/lib/python3.10/site-packages/mage_ai/orchestration/job_manager.py\", line 28, in add_job\n    self.queue.enqueue(job_id, target, *args, **kwargs)\n", "  File \"/usr/local/lib/python3.10/site-packages/mage_ai/orchestration/queue/process_queue.py\", line 108, in enqueue\n    self.start_worker_pool()\n", "  File \"/usr/local/lib/python3.10/site-packages/mage_ai/orchestration/queue/process_queue.py\", line 183, in start_worker_pool\n    self.worker_pool_proc.start()\n", "  File \"/usr/local/lib/python3.10/multiprocessing/process.py\", line 121, in start\n    self._popen = self._Popen(self)\n", "  File \"/usr/local/lib/python3.10/multiprocessing/context.py\", line 224, in _Popen\n    return _default_context.get_context().Process._Popen(process_obj)\n", "  File \"/usr/local/lib/python3.10/multiprocessing/context.py\", line 281, in _Popen\n    return Popen(process_obj)\n", "  File \"/usr/local/lib/python3.10/multiprocessing/popen_fork.py\", line 19, in __init__\n    self._launch(process_obj)\n", "  File \"/usr/local/lib/python3.10/multiprocessing/popen_fork.py\", line 71, in _launch\n    code = process_obj._bootstrap(parent_sentinel=child_r)\n", "  File \"/usr/local/lib/python3.10/multiprocessing/process.py\", line 314, in _bootstrap\n    self.run()\n", "  File \"/usr/local/lib/python3.10/multiprocessing/process.py\", line 108, in run\n    self._target(*self._args, **self._kwargs)\n", "  File \"/usr/local/lib/python3.10/site-packages/mage_ai/orchestration/queue/process_queue.py\", line 288, in poll_job_and_execute\n    worker.start()\n", "  File \"/usr/local/lib/python3.10/multiprocessing/process.py\", line 121, in start\n    self._popen = self._Popen(self)\n", "  File \"/usr/local/lib/python3.10/multiprocessing/context.py\", line 224, in _Popen\n    return _default_context.get_context().Process._Popen(process_obj)\n", "  File \"/usr/local/lib/python3.10/multiprocessing/context.py\", line 281, in _Popen\n    return Popen(process_obj)\n", "  File \"/usr/local/lib/python3.10/multiprocessing/popen_fork.py\", line 19, in __init__\n    self._launch(process_obj)\n", "  File \"/usr/local/lib/python3.10/multiprocessing/popen_fork.py\", line 71, in _launch\n    code = process_obj._bootstrap(parent_sentinel=child_r)\n", "  File \"/usr/local/lib/python3.10/multiprocessing/process.py\", line 314, in _bootstrap\n    self.run()\n", "  File \"/usr/local/lib/python3.10/site-packages/newrelic/api/background_task.py\", line 117, in wrapper\n    return wrapped(*args, **kwargs)\n", "  File \"/usr/local/lib/python3.10/site-packages/mage_ai/orchestration/queue/process_queue.py\", line 253, in run\n    start_session_and_run(args[1], *args[2], **args[3])\n", "  File \"/usr/local/lib/python3.10/site-packages/mage_ai/orchestration/db/process.py\", line 15, in start_session_and_run\n    results = target(*args)\n", "  File \"/usr/local/lib/python3.10/site-packages/mage_ai/orchestration/pipeline_scheduler_original.py\", line 1152, in run_block\n    return ExecutorFactory.get_block_executor(\n", "  File \"/usr/local/lib/python3.10/site-packages/mage_ai/data_preparation/executors/block_executor.py\", line 641, in execute\n    on_failure(\n", "  File \"/usr/local/lib/python3.10/site-packages/mage_ai/orchestration/db/__init__.py\", line 157, in func_with_rollback\n    return func(*args, **kwargs)\n", "  File \"/usr/local/lib/python3.10/site-packages/mage_ai/orchestration/pipeline_scheduler_original.py\", line 433, in on_block_failure\n    self.logger.exception(\n", "  File \"/usr/local/lib/python3.10/site-packages/mage_ai/data_preparation/logging/logger.py\", line 30, in exception\n    self.__send_message('exception', message, **kwargs)\n", "  File \"/usr/local/lib/python3.10/site-packages/mage_ai/data_preparation/logging/logger.py\", line 65, in __send_message\n    data['error_stack'] = traceback.format_stack(),\n"]], "error_stacktrace": ["'int' object has no attribute 'copy'"]}
Traceback (most recent call last):
  File "/usr/local/lib/python3.10/site-packages/mage_ai/data_preparation/executors/block_executor.py", line 613, in execute
    result = __execute_with_retry()
  File "/usr/local/lib/python3.10/site-packages/mage_ai/shared/retry.py", line 54, in retry_func
    raise e
  File "/usr/local/lib/python3.10/site-packages/mage_ai/shared/retry.py", line 38, in retry_func
    return func(*args, **kwargs)
  File "/usr/local/lib/python3.10/site-packages/mage_ai/data_preparation/executors/block_executor.py", line 588, in __execute_with_retry
    return self._execute(
  File "/usr/local/lib/python3.10/site-packages/mage_ai/data_preparation/executors/block_executor.py", line 1077, in _execute
    result = self.block.execute_sync(
  File "/usr/local/lib/python3.10/site-packages/mage_ai/data_preparation/models/block/__init__.py", line 1314, in execute_sync
    raise err
  File "/usr/local/lib/python3.10/site-packages/mage_ai/data_preparation/models/block/__init__.py", line 1223, in execute_sync
    output = self.execute_block(
  File "/usr/local/lib/python3.10/site-packages/mage_ai/data_preparation/models/block/__init__.py", line 1529, in execute_block
    outputs = self._execute_block(
  File "/usr/local/lib/python3.10/site-packages/mage_ai/data_preparation/models/block/__init__.py", line 1685, in _execute_block
    outputs = self.execute_block_function(
  File "/usr/local/lib/python3.10/site-packages/mage_ai/data_preparation/models/block/__init__.py", line 1724, in execute_block_function
    output = block_function_updated(*input_vars, **global_vars)
  File "<string>", line 25, in export_data_to_postgres
  File "/usr/local/lib/python3.10/site-packages/mage_ai/io/sql.py", line 279, in export
    df = clean_df_for_export(df, self.clean, dtypes)
  File "/usr/local/lib/python3.10/site-packages/mage_ai/io/export_utils.py", line 90, in clean_df_for_export
    copy_df = df.copy()
AttributeError: 'int' object has no attribute 'copy'
2024-03-21T07:54:01 {"cpu": 2.662109375, "cpu_total": 8, "cpu_usage": 0.332763671875, "memory": 1898.0, "memory_total": 8865.0, "memory_usage": 0.21410039481105472, "pipeline_run_id": 6169, "pipeline_schedule_id": 3, "pipeline_uuid": "etl_pipeline", "hostname": "3353dc602115", "level": "INFO", "message": "Pipeline etl_pipeline for run 6169 in schedule 3 is alive.", "timestamp": 1711007641.368013, "uuid": "be4fc65d0df840b6beb9b57a9239b897"}
